Traceback (most recent call last):
  File "/usr/local/lib/python3.9/dist-packages/jupyter_cache/executors/utils.py", line 58, in single_nb_execution
    executenb(
  File "/usr/local/lib/python3.9/dist-packages/nbclient/client.py", line 1204, in execute
    return NotebookClient(nb=nb, resources=resources, km=km, **kwargs).execute()
  File "/usr/local/lib/python3.9/dist-packages/nbclient/util.py", line 84, in wrapped
    return just_run(coro(*args, **kwargs))
  File "/usr/local/lib/python3.9/dist-packages/nbclient/util.py", line 62, in just_run
    return loop.run_until_complete(coro)
  File "/usr/lib/python3.9/asyncio/base_events.py", line 647, in run_until_complete
    return future.result()
  File "/usr/local/lib/python3.9/dist-packages/nbclient/client.py", line 663, in async_execute
    await self.async_execute_cell(
  File "/usr/local/lib/python3.9/dist-packages/nbclient/client.py", line 965, in async_execute_cell
    await self._check_raise_for_error(cell, cell_index, exec_reply)
  File "/usr/local/lib/python3.9/dist-packages/nbclient/client.py", line 862, in _check_raise_for_error
    raise CellExecutionError.from_cell_and_msg(cell, exec_reply_content)
nbclient.exceptions.CellExecutionError: An error occurred while executing the following cell:
------------------
from sklearn.metrics import plot_confusion_matrix

plot_confusion_matrix(clf, X_test_tfidf, y_test) 
plt.show()
------------------

[0;31m[0m
[0;31mImportError[0mTraceback (most recent call last)
[0;32m<ipython-input-16-ebf404216b11>[0m in [0;36m<cell line: 1>[0;34m()[0m
[0;32m----> 1[0;31m [0;32mfrom[0m [0msklearn[0m[0;34m.[0m[0mmetrics[0m [0;32mimport[0m [0mplot_confusion_matrix[0m[0;34m[0m[0;34m[0m[0m
[0m[1;32m      2[0m [0;34m[0m[0m
[1;32m      3[0m [0mplot_confusion_matrix[0m[0;34m([0m[0mclf[0m[0;34m,[0m [0mX_test_tfidf[0m[0;34m,[0m [0my_test[0m[0;34m)[0m[0;34m[0m[0;34m[0m[0m
[1;32m      4[0m [0mplt[0m[0;34m.[0m[0mshow[0m[0;34m([0m[0;34m)[0m[0;34m[0m[0;34m[0m[0m

[0;31mImportError[0m: cannot import name 'plot_confusion_matrix' from 'sklearn.metrics' (/usr/local/lib/python3.9/dist-packages/sklearn/metrics/__init__.py)

[0;31m---------------------------------------------------------------------------[0;32m
NOTE: If your import is failing due to a missing package, you can
manually install dependencies using either !pip or !apt.

To view examples of installing some common dependencies, click the
"Open Examples" button below.
[0;31m---------------------------------------------------------------------------[0m

ImportError: cannot import name 'plot_confusion_matrix' from 'sklearn.metrics' (/usr/local/lib/python3.9/dist-packages/sklearn/metrics/__init__.py)

