Traceback (most recent call last):
  File "/usr/local/lib/python3.8/dist-packages/jupyter_cache/executors/utils.py", line 51, in single_nb_execution
    executenb(
  File "/usr/local/lib/python3.8/dist-packages/nbclient/client.py", line 1204, in execute
    return NotebookClient(nb=nb, resources=resources, km=km, **kwargs).execute()
  File "/usr/local/lib/python3.8/dist-packages/nbclient/util.py", line 84, in wrapped
    return just_run(coro(*args, **kwargs))
  File "/usr/local/lib/python3.8/dist-packages/nbclient/util.py", line 62, in just_run
    return loop.run_until_complete(coro)
  File "/usr/lib/python3.8/asyncio/base_events.py", line 616, in run_until_complete
    return future.result()
  File "/usr/local/lib/python3.8/dist-packages/nbclient/client.py", line 663, in async_execute
    await self.async_execute_cell(
  File "/usr/local/lib/python3.8/dist-packages/nbclient/client.py", line 965, in async_execute_cell
    await self._check_raise_for_error(cell, cell_index, exec_reply)
  File "/usr/local/lib/python3.8/dist-packages/nbclient/client.py", line 862, in _check_raise_for_error
    raise CellExecutionError.from_cell_and_msg(cell, exec_reply_content)
nbclient.exceptions.CellExecutionError: An error occurred while executing the following cell:
------------------
import requests
from bs4 import BeautifulSoup

pta = []

for i in range(10,61):
  URL = "https://pta.trunojoyo.ac.id/c_search/byprod/10/" + str(i+1)
  r = requests.get(URL)
  soup = BeautifulSoup(r.text, 'html.parser')
  items = soup.find('div', {'id':'content_journal'})

  for it in items.findAll('li',{'data-cat':'#luxury'}):
    tempNama = it.span.text.strip('\n').replace('Penulis : ', '')
    # links = it.findAll('div', {'style':'margin: 25px 0px 15px 0px;'})
    link = it.find('a', 'gray button')['href']
    req = requests.get(link)
    soup2 = BeautifulSoup(req.text, 'html.parser')
    abstraks = soup2.findAll('div', {'style':'margin: 15px 15px 15px 15px;'})
    abstrak = soup2.find('p', {'align':'justify'}).text
  
    tempNIM = link.replace('https://pta.trunojoyo.ac.id/welcome/detail/', '')

    pta.append([it.a.text.strip('\n'), tempNIM, tempNama, abstrak])
    
pta_df = pd.DataFrame(pta, columns=['Judul', 'NIM', 'Penulis', 'Abstrak'])
pta_df
------------------

[0;31m[0m
[0;31mOSError[0mTraceback (most recent call last)
[0;32m/usr/local/lib/python3.8/dist-packages/urllib3/connection.py[0m in [0;36m_new_conn[0;34m(self)[0m
[1;32m    157[0m         [0;32mtry[0m[0;34m:[0m[0;34m[0m[0;34m[0m[0m
[0;32m--> 158[0;31m             conn = connection.create_connection(
[0m[1;32m    159[0m                 (self._dns_host, self.port), self.timeout, **extra_kw)

[0;32m/usr/local/lib/python3.8/dist-packages/urllib3/util/connection.py[0m in [0;36mcreate_connection[0;34m(address, timeout, source_address, socket_options)[0m
[1;32m     79[0m     [0;32mif[0m [0merr[0m [0;32mis[0m [0;32mnot[0m [0;32mNone[0m[0;34m:[0m[0;34m[0m[0;34m[0m[0m
[0;32m---> 80[0;31m         [0;32mraise[0m [0merr[0m[0;34m[0m[0;34m[0m[0m
[0m[1;32m     81[0m [0;34m[0m[0m

[0;32m/usr/local/lib/python3.8/dist-packages/urllib3/util/connection.py[0m in [0;36mcreate_connection[0;34m(address, timeout, source_address, socket_options)[0m
[1;32m     69[0m                 [0msock[0m[0;34m.[0m[0mbind[0m[0;34m([0m[0msource_address[0m[0;34m)[0m[0;34m[0m[0;34m[0m[0m
[0;32m---> 70[0;31m             [0msock[0m[0;34m.[0m[0mconnect[0m[0;34m([0m[0msa[0m[0;34m)[0m[0;34m[0m[0;34m[0m[0m
[0m[1;32m     71[0m             [0;32mreturn[0m [0msock[0m[0;34m[0m[0;34m[0m[0m

[0;31mOSError[0m: [Errno 101] Network is unreachable

During handling of the above exception, another exception occurred:

[0;31mNewConnectionError[0mTraceback (most recent call last)
[0;32m/usr/local/lib/python3.8/dist-packages/urllib3/connectionpool.py[0m in [0;36murlopen[0;34m(self, method, url, body, headers, retries, redirect, assert_same_host, timeout, pool_timeout, release_conn, chunked, body_pos, **response_kw)[0m
[1;32m    596[0m             [0;31m# Make the request on the httplib connection object.[0m[0;34m[0m[0;34m[0m[0;34m[0m[0m
[0;32m--> 597[0;31m             httplib_response = self._make_request(conn, method, url,
[0m[1;32m    598[0m                                                   [0mtimeout[0m[0;34m=[0m[0mtimeout_obj[0m[0;34m,[0m[0;34m[0m[0;34m[0m[0m

[0;32m/usr/local/lib/python3.8/dist-packages/urllib3/connectionpool.py[0m in [0;36m_make_request[0;34m(self, conn, method, url, timeout, chunked, **httplib_request_kw)[0m
[1;32m    342[0m         [0;32mtry[0m[0;34m:[0m[0;34m[0m[0;34m[0m[0m
[0;32m--> 343[0;31m             [0mself[0m[0;34m.[0m[0m_validate_conn[0m[0;34m([0m[0mconn[0m[0;34m)[0m[0;34m[0m[0;34m[0m[0m
[0m[1;32m    344[0m         [0;32mexcept[0m [0;34m([0m[0mSocketTimeout[0m[0;34m,[0m [0mBaseSSLError[0m[0;34m)[0m [0;32mas[0m [0me[0m[0;34m:[0m[0;34m[0m[0;34m[0m[0m

[0;32m/usr/local/lib/python3.8/dist-packages/urllib3/connectionpool.py[0m in [0;36m_validate_conn[0;34m(self, conn)[0m
[1;32m    838[0m         [0;32mif[0m [0;32mnot[0m [0mgetattr[0m[0;34m([0m[0mconn[0m[0;34m,[0m [0;34m'sock'[0m[0;34m,[0m [0;32mNone[0m[0;34m)[0m[0;34m:[0m  [0;31m# AppEngine might not have  `.sock`[0m[0;34m[0m[0;34m[0m[0m
[0;32m--> 839[0;31m             [0mconn[0m[0;34m.[0m[0mconnect[0m[0;34m([0m[0;34m)[0m[0;34m[0m[0;34m[0m[0m
[0m[1;32m    840[0m [0;34m[0m[0m

[0;32m/usr/local/lib/python3.8/dist-packages/urllib3/connection.py[0m in [0;36mconnect[0;34m(self)[0m
[1;32m    300[0m         [0;31m# Add certificate verification[0m[0;34m[0m[0;34m[0m[0;34m[0m[0m
[0;32m--> 301[0;31m         [0mconn[0m [0;34m=[0m [0mself[0m[0;34m.[0m[0m_new_conn[0m[0;34m([0m[0;34m)[0m[0;34m[0m[0;34m[0m[0m
[0m[1;32m    302[0m         [0mhostname[0m [0;34m=[0m [0mself[0m[0;34m.[0m[0mhost[0m[0;34m[0m[0;34m[0m[0m

[0;32m/usr/local/lib/python3.8/dist-packages/urllib3/connection.py[0m in [0;36m_new_conn[0;34m(self)[0m
[1;32m    166[0m         [0;32mexcept[0m [0mSocketError[0m [0;32mas[0m [0me[0m[0;34m:[0m[0;34m[0m[0;34m[0m[0m
[0;32m--> 167[0;31m             raise NewConnectionError(
[0m[1;32m    168[0m                 self, "Failed to establish a new connection: %s" % e)

[0;31mNewConnectionError[0m: <urllib3.connection.VerifiedHTTPSConnection object at 0x7f82a24d59d0>: Failed to establish a new connection: [Errno 101] Network is unreachable

During handling of the above exception, another exception occurred:

[0;31mMaxRetryError[0mTraceback (most recent call last)
[0;32m/usr/local/lib/python3.8/dist-packages/requests/adapters.py[0m in [0;36msend[0;34m(self, request, stream, timeout, verify, cert, proxies)[0m
[1;32m    438[0m             [0;32mif[0m [0;32mnot[0m [0mchunked[0m[0;34m:[0m[0;34m[0m[0;34m[0m[0m
[0;32m--> 439[0;31m                 resp = conn.urlopen(
[0m[1;32m    440[0m                     [0mmethod[0m[0;34m=[0m[0mrequest[0m[0;34m.[0m[0mmethod[0m[0;34m,[0m[0;34m[0m[0;34m[0m[0m

[0;32m/usr/local/lib/python3.8/dist-packages/urllib3/connectionpool.py[0m in [0;36murlopen[0;34m(self, method, url, body, headers, retries, redirect, assert_same_host, timeout, pool_timeout, release_conn, chunked, body_pos, **response_kw)[0m
[1;32m    636[0m [0;34m[0m[0m
[0;32m--> 637[0;31m             retries = retries.increment(method, url, error=e, _pool=self,
[0m[1;32m    638[0m                                         _stacktrace=sys.exc_info()[2])

[0;32m/usr/local/lib/python3.8/dist-packages/urllib3/util/retry.py[0m in [0;36mincrement[0;34m(self, method, url, response, error, _pool, _stacktrace)[0m
[1;32m    398[0m         [0;32mif[0m [0mnew_retry[0m[0;34m.[0m[0mis_exhausted[0m[0;34m([0m[0;34m)[0m[0;34m:[0m[0;34m[0m[0;34m[0m[0m
[0;32m--> 399[0;31m             [0;32mraise[0m [0mMaxRetryError[0m[0;34m([0m[0m_pool[0m[0;34m,[0m [0murl[0m[0;34m,[0m [0merror[0m [0;32mor[0m [0mResponseError[0m[0;34m([0m[0mcause[0m[0;34m)[0m[0;34m)[0m[0;34m[0m[0;34m[0m[0m
[0m[1;32m    400[0m [0;34m[0m[0m

[0;31mMaxRetryError[0m: HTTPSConnectionPool(host='pta.trunojoyo.ac.id', port=443): Max retries exceeded with url: /c_search/byprod/10/11 (Caused by NewConnectionError('<urllib3.connection.VerifiedHTTPSConnection object at 0x7f82a24d59d0>: Failed to establish a new connection: [Errno 101] Network is unreachable'))

During handling of the above exception, another exception occurred:

[0;31mConnectionError[0mTraceback (most recent call last)
[0;32m<ipython-input-10-7930a43a3929>[0m in [0;36m<module>[0;34m[0m
[1;32m      6[0m [0;32mfor[0m [0mi[0m [0;32min[0m [0mrange[0m[0;34m([0m[0;36m10[0m[0;34m,[0m[0;36m61[0m[0;34m)[0m[0;34m:[0m[0;34m[0m[0;34m[0m[0m
[1;32m      7[0m   [0mURL[0m [0;34m=[0m [0;34m"https://pta.trunojoyo.ac.id/c_search/byprod/10/"[0m [0;34m+[0m [0mstr[0m[0;34m([0m[0mi[0m[0;34m+[0m[0;36m1[0m[0;34m)[0m[0;34m[0m[0;34m[0m[0m
[0;32m----> 8[0;31m   [0mr[0m [0;34m=[0m [0mrequests[0m[0;34m.[0m[0mget[0m[0;34m([0m[0mURL[0m[0;34m)[0m[0;34m[0m[0;34m[0m[0m
[0m[1;32m      9[0m   [0msoup[0m [0;34m=[0m [0mBeautifulSoup[0m[0;34m([0m[0mr[0m[0;34m.[0m[0mtext[0m[0;34m,[0m [0;34m'html.parser'[0m[0;34m)[0m[0;34m[0m[0;34m[0m[0m
[1;32m     10[0m   [0mitems[0m [0;34m=[0m [0msoup[0m[0;34m.[0m[0mfind[0m[0;34m([0m[0;34m'div'[0m[0;34m,[0m [0;34m{[0m[0;34m'id'[0m[0;34m:[0m[0;34m'content_journal'[0m[0;34m}[0m[0;34m)[0m[0;34m[0m[0;34m[0m[0m

[0;32m/usr/local/lib/python3.8/dist-packages/requests/api.py[0m in [0;36mget[0;34m(url, params, **kwargs)[0m
[1;32m     74[0m [0;34m[0m[0m
[1;32m     75[0m     [0mkwargs[0m[0;34m.[0m[0msetdefault[0m[0;34m([0m[0;34m'allow_redirects'[0m[0;34m,[0m [0;32mTrue[0m[0;34m)[0m[0;34m[0m[0;34m[0m[0m
[0;32m---> 76[0;31m     [0;32mreturn[0m [0mrequest[0m[0;34m([0m[0;34m'get'[0m[0;34m,[0m [0murl[0m[0;34m,[0m [0mparams[0m[0;34m=[0m[0mparams[0m[0;34m,[0m [0;34m**[0m[0mkwargs[0m[0;34m)[0m[0;34m[0m[0;34m[0m[0m
[0m[1;32m     77[0m [0;34m[0m[0m
[1;32m     78[0m [0;34m[0m[0m

[0;32m/usr/local/lib/python3.8/dist-packages/requests/api.py[0m in [0;36mrequest[0;34m(method, url, **kwargs)[0m
[1;32m     59[0m     [0;31m# cases, and look like a memory leak in others.[0m[0;34m[0m[0;34m[0m[0;34m[0m[0m
[1;32m     60[0m     [0;32mwith[0m [0msessions[0m[0;34m.[0m[0mSession[0m[0;34m([0m[0;34m)[0m [0;32mas[0m [0msession[0m[0;34m:[0m[0;34m[0m[0;34m[0m[0m
[0;32m---> 61[0;31m         [0;32mreturn[0m [0msession[0m[0;34m.[0m[0mrequest[0m[0;34m([0m[0mmethod[0m[0;34m=[0m[0mmethod[0m[0;34m,[0m [0murl[0m[0;34m=[0m[0murl[0m[0;34m,[0m [0;34m**[0m[0mkwargs[0m[0;34m)[0m[0;34m[0m[0;34m[0m[0m
[0m[1;32m     62[0m [0;34m[0m[0m
[1;32m     63[0m [0;34m[0m[0m

[0;32m/usr/local/lib/python3.8/dist-packages/requests/sessions.py[0m in [0;36mrequest[0;34m(self, method, url, params, data, headers, cookies, files, auth, timeout, allow_redirects, proxies, hooks, stream, verify, cert, json)[0m
[1;32m    540[0m         }
[1;32m    541[0m         [0msend_kwargs[0m[0;34m.[0m[0mupdate[0m[0;34m([0m[0msettings[0m[0;34m)[0m[0;34m[0m[0;34m[0m[0m
[0;32m--> 542[0;31m         [0mresp[0m [0;34m=[0m [0mself[0m[0;34m.[0m[0msend[0m[0;34m([0m[0mprep[0m[0;34m,[0m [0;34m**[0m[0msend_kwargs[0m[0;34m)[0m[0;34m[0m[0;34m[0m[0m
[0m[1;32m    543[0m [0;34m[0m[0m
[1;32m    544[0m         [0;32mreturn[0m [0mresp[0m[0;34m[0m[0;34m[0m[0m

[0;32m/usr/local/lib/python3.8/dist-packages/requests/sessions.py[0m in [0;36msend[0;34m(self, request, **kwargs)[0m
[1;32m    653[0m [0;34m[0m[0m
[1;32m    654[0m         [0;31m# Send the request[0m[0;34m[0m[0;34m[0m[0;34m[0m[0m
[0;32m--> 655[0;31m         [0mr[0m [0;34m=[0m [0madapter[0m[0;34m.[0m[0msend[0m[0;34m([0m[0mrequest[0m[0;34m,[0m [0;34m**[0m[0mkwargs[0m[0;34m)[0m[0;34m[0m[0;34m[0m[0m
[0m[1;32m    656[0m [0;34m[0m[0m
[1;32m    657[0m         [0;31m# Total elapsed time of the request (approximately)[0m[0;34m[0m[0;34m[0m[0;34m[0m[0m

[0;32m/usr/local/lib/python3.8/dist-packages/requests/adapters.py[0m in [0;36msend[0;34m(self, request, stream, timeout, verify, cert, proxies)[0m
[1;32m    514[0m                 [0;32mraise[0m [0mSSLError[0m[0;34m([0m[0me[0m[0;34m,[0m [0mrequest[0m[0;34m=[0m[0mrequest[0m[0;34m)[0m[0;34m[0m[0;34m[0m[0m
[1;32m    515[0m [0;34m[0m[0m
[0;32m--> 516[0;31m             [0;32mraise[0m [0mConnectionError[0m[0;34m([0m[0me[0m[0;34m,[0m [0mrequest[0m[0;34m=[0m[0mrequest[0m[0;34m)[0m[0;34m[0m[0;34m[0m[0m
[0m[1;32m    517[0m [0;34m[0m[0m
[1;32m    518[0m         [0;32mexcept[0m [0mClosedPoolError[0m [0;32mas[0m [0me[0m[0;34m:[0m[0;34m[0m[0;34m[0m[0m

[0;31mConnectionError[0m: HTTPSConnectionPool(host='pta.trunojoyo.ac.id', port=443): Max retries exceeded with url: /c_search/byprod/10/11 (Caused by NewConnectionError('<urllib3.connection.VerifiedHTTPSConnection object at 0x7f82a24d59d0>: Failed to establish a new connection: [Errno 101] Network is unreachable'))
ConnectionError: HTTPSConnectionPool(host='pta.trunojoyo.ac.id', port=443): Max retries exceeded with url: /c_search/byprod/10/11 (Caused by NewConnectionError('<urllib3.connection.VerifiedHTTPSConnection object at 0x7f82a24d59d0>: Failed to establish a new connection: [Errno 101] Network is unreachable'))

